Workbook

Sheet seq-metadata_constructed
A1: Seq_ID | B1: Genome_ID (not_unique!!, original_from_accession_map, do_not_delete!!) | C1: Genome_ID (not_unique!!, for lookup) | D1: year | E1: Phylogroup_lineage | F1: Gender | G1: Immunosuppression | H1: Summe.der.Punkte.for.Charlson.Comorbidity.Index | I1: age | J1: papGII | K1: CTR_RES | L1: Invasiveness | M1: ICU.stay | N1: thirty_day_mortality_since_sample | O1: UTI.symptoms
A2: SAMEA111330906 | B2: 115309-18 | C2: 115309-18 | D2: =VLOOKUP($C2, Egli_UPEC_metadata_provided!$A$2:$M$826, 3, FALSE) -> 2018 | E2: =VLOOKUP($C2, Egli_UPEC_metadata_provided!$A$2:$M$826, 4, FALSE) -> B2-2 | F2: =VLOOKUP($C2, Egli_UPEC_metadata_provided!$A$2:$M$826, 5, FALSE) -> w | G2: =VLOOKUP($C2, Egli_UPEC_metadata_provided!$A$2:$M$826, 6, FALSE) -> 0 | H2: =VLOOKUP($C2, Egli_UPEC_metadata_provided!$A$2:$M$826, 7, FALSE) -> 0 | I2: =VLOOKUP($C2, Egli_UPEC_metadata_provided!$A$2:$M$826, 8, FALSE) -> 93.37799 | J2: =VLOOKUP($C2, Egli_UPEC_metadata_provided!$A$2:$M$826, 9, FALSE) -> FALSE | K2: =VLOOKUP($C2, Egli_UPEC_metadata_provided!$A$2:$M$826, 10, FALSE) -> 0 | L2: =VLOOKUP($C2, Egli_UPEC_metadata_provided!$A$2:$M$826, 11, FALSE) -> invasive | M2: =VLOOKUP($C2, Egli_UPEC_metadata_provided!$A$2:$M$826, 12, FALSE) -> 0 | N2: =VLOOKUP($C2, Egli_UPEC_metadata_provided!$A$2:$M$826, 13, FALSE) -> 0 | O2: =VLOOKUP($C2, Egli_UPEC_metadata_provided!$A$2:$N$826, 14, FALSE) -> 0
A3: SAMEA111330907 | B3: 115325-18 | C3: 115325-18 | D3: =VLOOKUP($C3, Egli_UPEC_metadata_provided!$A$2:$M$826, 3, FALSE) -> 2018 | E3: =VLOOKUP($C3, Egli_UPEC_metadata_provided!$A$2:$M$826, 4, FALSE) -> B2-2 | F3: =VLOOKUP($C3, Egli_UPEC_metadata_provided!$A$2:$M$826, 5, FALSE) -> w | G3: =VLOOKUP($C3, Egli_UPEC_metadata_provided!$A$2:$M$826, 6, FALSE) -> 0 | H3: =VLOOKUP($C3, Egli_UPEC_metadata_provided!$A$2:$M$826, 7, FALSE) -> 0 | I3: =VLOOKUP($C3, Egli_UPEC_metadata_provided!$A$2:$M$826, 8, FALSE) -> 65.038961 | J3: =VLOOKUP($C3, Egli_UPEC_metadata_provided!$A$2:$M$826, 9, FALSE) -> TRUE | K3: =VLOOKUP($C3, Egli_UPEC_metadata_provided!$A$2:$M$826, 10, FALSE) -> NA | L3: =VLOOKUP($C3, Egli_UPEC_metadata_provided!$A$2:$M$826, 11, FALSE) -> invasive | M3: =VLOOKUP($C3, Egli_UPEC_metadata_provided!$A$2:$M$826, 12, FALSE) -> 0 | N3: =VLOOKUP($C3, Egli_UPEC_metadata_provided!$A$2:$M$826, 13, FALSE) -> 0 | O3: =VLOOKUP($C3, Egli_UPEC_metadata_provided!$A$2:$N$826, 14, FALSE) -> 0
A4: SAMEA111330908 | B4: 115366-18 | C4: 115366-18 | D4: =VLOOKUP($C4, Egli_UPEC_metadata_provided!$A$2:$M$826, 3, FALSE) -> 2018 | E4: =VLOOKUP($C4, Egli_UPEC_metadata_provided!$A$2:$M$826, 4, FALSE) -> D1 | F4: =VLOOKUP($C4, Egli_UPEC_metadata_provided!$A$2:$M$826, 5, FALSE) -> m | G4: =VLOOKUP($C4, Egli_UPEC_metadata_provided!$A$2:$M$826, 6, FALSE) -> 0 | H4: =VLOOKUP($C4, Egli_UPEC_metadata_provided!$A$2:$M$826, 7, FALSE) -> 3 | I4: =VLOOKUP($C4, Egli_UPEC_metadata_provided!$A$2:$M$826, 8, FALSE) -> 66.373206 | J4: =VLOOKUP($C4, Egli_UPEC_metadata_provided!$A$2:$M$826, 9, FALSE) -> FALSE | K4: =VLOOKUP($C4, Egli_UPEC_metadata_provided!$A$2:$M$826, 10, FALSE) -> 0 | L4: =VLOOKUP($C4, Egli_UPEC_metadata_provided!$A$2:$M$826, 11, FALSE) -> invasive | M4: =VLOOKUP($C4, Egli_UPEC_metadata_provided!$A$2:$M$826, 12, FALSE) -> 0 | N4: =VLOOKUP($C4, Egli_UPEC_metadata_provided!$A$2:$M$826, 13, FALSE) -> 0 | O4: =VLOOKUP($C4, Egli_UPEC_metadata_provided!$A$2:$N$826, 14, FALSE) -> 1
A5: SAMEA111330909 | B5: 115450-18 | C5: 115450-18 | D5: =VLOOKUP($C5, Egli_UPEC_metadata_provided!$A$2:$M$826, 3, FALSE) -> 2018 | E5: =VLOOKUP($C5, Egli_UPEC_metadata_provided!$A$2:$M$826, 4, FALSE) -> D1 | F5: =VLOOKUP($C5, Egli_UPEC_metadata_provided!$A$2:$M$826, 5, FALSE) -> w | G5: =VLOOKUP($C5, Egli_UPEC_metadata_provided!$A$2:$M$826, 6, FALSE) -> 0 | H5: =VLOOKUP($C5, Egli_UPEC_metadata_provided!$A$2:$M$826, 7, FALSE) -> 3 | I5: =VLOOKUP($C5, Egli_UPEC_metadata_provided!$A$2:$M$826, 8, FALSE) -> 76.369105 | J5: =VLOOKUP($C5, Egli_UPEC_metadata_provided!$A$2:$M$826, 9, FALSE) -> TRUE | K5: =VLOOKUP($C5, Egli_UPEC_metadata_provided!$A$2:$M$826, 10, FALSE) -> 0 | L5: =VLOOKUP($C5, Egli_UPEC_metadata_provided!$A$2:$M$826, 11, FALSE) -> invasive | M5: =VLOOKUP($C5, Egli_UPEC_metadata_provided!$A$2:$M$826, 12, FALSE) -> 1 | N5: =VLOOKUP($C5, Egli_UPEC_metadata_provided!$A$2:$M$826, 13, FALSE) -> 0 | O5: =VLOOKUP($C5, Egli_UPEC_metadata_provided!$A$2:$N$826, 14, FALSE) -> 0
A6: SAMEA111330910 | B6: 115672-18 | C6: 115672-18 | D6: =VLOOKUP($C6, Egli_UPEC_metadata_provided!$A$2:$M$826, 3, FALSE) -> 2018 | E6: =VLOOKUP($C6, Egli_UPEC_metadata_provided!$A$2:$M$826, 4, FALSE) -> B2-2 | F6: =VLOOKUP($C6, Egli_UPEC_metadata_provided!$A$2:$M$826, 5, FALSE) -> w | G6: =VLOOKUP($C6, Egli_UPEC_metadata_provided!$A$2:$M$826, 6, FALSE) -> 0 | H6: =VLOOKUP($C6, Egli_UPEC_metadata_provided!$A$2:$M$826, 7, FALSE) -> 3 | I6: =VLOOKUP($C6, Egli_UPEC_metadata_provided!$A$2:$M$826, 8, FALSE) -> 83.991798 | J6: =VLOOKUP($C6, Egli_UPEC_metadata_provided!$A$2:$M$826, 9, FALSE) -> TRUE | K6: =VLOOKUP($C6, Egli_UPEC_metadata_provided!$A$2:$M$826, 10, FALSE) -> NA | L6: =VLOOKUP($C6, Egli_UPEC_metadata_provided!$A$2:$M$826, 11, FALSE) -> invasive | M6: =VLOOKUP($C6, Egli_UPEC_metadata_provided!$A$2:$M$826, 12, FALSE) -> 0 | N6: =VLOOKUP($C6, Egli_UPEC_metadata_provided!$A$2:$M$826, 13, FALSE) -> 0 | O6: =VLOOKUP($C6, Egli_UPEC_metadata_provided!$A$2:$N$826, 14, FALSE) -> 0
A7: SAMEA111330911 | B7: 116096-18 | C7: 116096-18 | D7: =VLOOKUP($C7, Egli_UPEC_metadata_provided!$A$2:$M$826, 3, FALSE) -> 2018 | E7: =VLOOKUP($C7, Egli_UPEC_metadata_provided!$A$2:$M$826, 4, FALSE) -> D2 | F7: =VLOOKUP($C7, Egli_UPEC_metadata_provided!$A$2:$M$826, 5, FALSE) -> w | G7: =VLOOKUP($C7, Egli_UPEC_metadata_provided!$A$2:$M$826, 6, FALSE) -> 1 | H7: =VLOOKUP($C7, Egli_UPEC_metadata_provided!$A$2:$M$826, 7, FALSE) -> 4 | I7: =VLOOKUP($C7, Egli_UPEC_metadata_provided!$A$2:$M$826, 8, FALSE) -> 28.995215 | J7: =VLOOKUP($C7, Egli_UPEC_metadata_provided!$A$2:$M$826, 9, FALSE) -> FALSE | K7: =VLOOKUP($C7, Egli_UPEC_metadata_provided!$A$2:$M$826, 10, FALSE) -> 0 | L7: =VLOOKUP($C7, Egli_UPEC_metadata_provided!$A$2:$M$826, 11, FALSE) -> invasive | M7: =VLOOKUP($C7, Egli_UPEC_metadata_provided!$A$2:$M$826, 12, FALSE) -> 0 | N7: =VLOOKUP($C7, Egli_UPEC_metadata_provided!$A$2:$M$826, 13, FALSE) -> 0 | O7: =VLOOKUP($C7, Egli_UPEC_metadata_provided!$A$2:$N$826, 14, FALSE) -> 0
A8: SAMEA111330913 | B8: 116960-18 | C8: 116960-18 | D8: =VLOOKUP($C8, Egli_UPEC_metadata_provided!$A$2:$M$826, 3, FALSE) -> 2018 | E8: =VLOOKUP($C8, Egli_UPEC_metadata_provided!$A$2:$M$826, 4, FALSE) -> B1 | F8: =VLOOKUP($C8, Egli_UPEC_metadata_provided!$A$2:$M$826, 5, FALSE) -> m | G8: =VLOOKUP($C8, Egli_UPEC_metadata_provided!$A$2:$M$826, 6, FALSE) -> 1 | H8: =VLOOKUP($C8, Egli_UPEC_metadata_provided!$A$2:$M$826, 7, FALSE) -> 4 | I8: =VLOOKUP($C8, Egli_UPEC_metadata_provided!$A$2:$M$826, 8, FALSE) -> 65.935748 | J8: =VLOOKUP($C8, Egli_UPEC_metadata_provided!$A$2:$M$826, 9, FALSE) -> FALSE | K8: =VLOOKUP($C8, Egli_UPEC_metadata_provided!$A$2:$M$826, 10, FALSE) -> 0 | L8: =VLOOKUP($C8, Egli_UPEC_metadata_provided!$A$2:$M$826, 11, FALSE) -> invasive | M8: =VLOOKUP($C8, Egli_UPEC_metadata_provided!$A$2:$M$826, 12, FALSE) -> 0 | N8: =VLOOKUP($C8, Egli_UPEC_metadata_provided!$A$2:$M$826, 13, FALSE) -> 0 | O8: =VLOOKUP($C8, Egli_UPEC_metadata_provided!$A$2:$N$826, 14, FALSE) -> 0
A9: SAMEA111330917 | B9: 117050-18 | C9: 117050-18 | D9: =VLOOKUP($C9, Egli_UPEC_metadata_provided!$A$2:$M$826, 3, FALSE) -> 2018 | E9: =VLOOKUP($C9, Egli_UPEC_metadata_provided!$A$2:$M$826, 4, FALSE) -> B2-2 | F9: =VLOOKUP($C9, Egli_UPEC_metadata_provided!$A$2:$M$826, 5, FALSE) -> w | G9: =VLOOKUP($C9, Egli_UPEC_metadata_provided!$A$2:$M$826, 6, FALSE) -> 0 | H9: =VLOOKUP($C9, Egli_UPEC_metadata_provided!$A$2:$M$826, 7, FALSE) -> 5 | I9: =VLOOKUP($C9, Egli_UPEC_metadata_provided!$A$2:$M$826, 8, FALSE) -> 74.868079 | J9: =VLOOKUP($C9, Egli_UPEC_metadata_provided!$A$2:$M$826, 9, FALSE) -> TRUE | K9: =VLOOKUP($C9, Egli_UPEC_metadata_provided!$A$2:$M$826, 10, FALSE) -> 0 | L9: =VLOOKUP($C9, Egli_UPEC_metadata_provided!$A$2:$M$826, 11, FALSE) -> invasive | M9: =VLOOKUP($C9, Egli_UPEC_metadata_provided!$A$2:$M$826, 12, FALSE) -> 0 | N9: =VLOOKUP($C9, Egli_UPEC_metadata_provided!$A$2:$M$826, 13, FALSE) -> 0 | O9: =VLOOKUP($C9, Egli_UPEC_metadata_provided!$A$2:$N$826, 14, FALSE) -> 0
A10: SAMEA111330918 | B10: 117243-18 | C10: 117243-18 | D10: =VLOOKUP($C10, Egli_UPEC_metadata_provided!$A$2:$M$826, 3, FALSE) -> 2018 | E10: =VLOOKUP($C10, Egli_UPEC_metadata_provided!$A$2:$M$826, 4, FALSE) -> B2-2 | F10: =VLOOKUP($C10, Egli_UPEC_metadata_provided!$A$2:$M$826, 5, FALSE) -> m | G10: =VLOOKUP($C10, Egli_UPEC_metadata_provided!$A$2:$M$826, 6, FALSE) -> 0 | H10: =VLOOKUP($C10, Egli_UPEC_metadata_provided!$A$2:$M$826, 7, FALSE) -> 8 | I10: =VLOOKUP($C10, Egli_UPEC_metadata_provided!$A$2:$M$826, 8, FALSE) -> 76.330827 | J10: =VLOOKUP($C10, Egli_UPEC_metadata_provided!$A$2:$M$826, 9, FALSE) -> TRUE | K10: =VLOOKUP($C10, Egli_UPEC_metadata_provided!$A$2:$M$826, 10, FALSE) -> 0 | L10: =VLOOKUP($C10, Egli_UPEC_metadata_provided!$A$2:$M$826, 11, FALSE) -> invasive | M10: =VLOOKUP($C10, Egli_UPEC_metadata_provided!$A$2:$M$826, 12, FALSE) -> 0 | N10: =VLOOKUP($C10, Egli_UPEC_metadata_provided!$A$2:$M$826, 13, FALSE) -> 0 | O10: =VLOOKUP($C10, Egli_UPEC_metadata_provided!$A$2:$N$826, 14, FALSE) -> 0
A11: SAMEA111330919 | B11: 117301-18 | C11: 117301-18 | D11: =VLOOKUP($C11, Egli_UPEC_metadata_provided!$A$2:$M$826, 3, FALSE) -> 2018 | E11: =VLOOKUP($C11, Egli_UPEC_metadata_provided!$A$2:$M$826, 4, FALSE) -> D1 | F11: =VLOOKUP($C11, Egli_UPEC_metadata_provided!$A$2:$M$826, 5, FALSE) -> m | G11: =VLOOKUP($C11, Egli_UPEC_metadata_provided!$A$2:$M$826, 6, FALSE) -> 0 | H11: =VLOOKUP($C11, Egli_UPEC_metadata_provided!$A$2:$M$826, 7, FALSE) -> 0 | I11: =VLOOKUP($C11, Egli_UPEC_metadata_provided!$A$2:$M$826, 8, FALSE) -> 62.045113 | J11: =VLOOKUP($C11, Egli_UPEC_metadata_provided!$A$2:$M$826, 9, FALSE) -> FALSE | K11: =VLOOKUP($C11, Egli_UPEC_metadata_provided!$A$2:$M$826, 10, FALSE) -> 0 | L11: =VLOOKUP($C11, Egli_UPEC_metadata_provided!$A$2:$M$826, 11, FALSE) -> invasive | M11: =VLOOKUP($C11, Egli_UPEC_metadata_provided!$A$2:$M$826, 12, FALSE) -> 0 | N11: =VLOOKUP($C11, Egli_UPEC_metadata_provided!$A$2:$M$826, 13, FALSE) -> 0 | O11: =VLOOKUP($C11, Egli_UPEC_metadata_provided!$A$2:$N$826, 14, FALSE) -> 1
A12: SAMEA111330920 | B12: 117315-18 | C12: 117315-18 | D12: =VLOOKUP($C12, Egli_UPEC_metadata_provided!$A$2:$M$826, 3, FALSE) -> 2018 | E12: =VLOOKUP($C12, Egli_UPEC_metadata_provided!$A$2:$M$826, 4, FALSE) -> B2-2 | F12: =VLOOKUP($C12, Egli_UPEC_metadata_provided!$A$2:$M$826, 5, FALSE) -> m | G12: =VLOOKUP($C12, Egli_UPEC_metadata_provided!$A$2:$M$826, 6, FALSE) -> 0 | H12: =VLOOKUP($C12, Egli_UPEC_metadata_provided!$A$2:$M$826, 7, FALSE) -> 1 | I12: =VLOOKUP($C12, Egli_UPEC_metadata_provided!$A$2:$M$826, 8, FALSE) -> 94.859877 | J12: =VLOOKUP($C12, Egli_UPEC_metadata_provided!$A$2:$M$826, 9, FALSE) -> FALSE | K12: =VLOOKUP($C12, Egli_UPEC_metadata_provided!$A$2:$M$826, 10, FALSE) -> 0 | L12: =VLOOKUP($C12, Egli_UPEC_metadata_provided!$A$2:$M$826, 11, FALSE) -> invasive | M12: =VLOOKUP($C12, Egli_UPEC_metadata_provided!$A$2:$M$826, 12, FALSE) -> 0 | N12: =VLOOKUP($C12, Egli_UPEC_metadata_provided!$A$2:$M$826, 13, FALSE) -> 0 | O12: =VLOOKUP($C12, Egli_UPEC_metadata_provided!$A$2:$N$826, 14, FALSE) -> 1
A13: SAMEA111330922 | B13: 117378-18 | C13: 117378-18 | D13: =VLOOKUP($C13, Egli_UPEC_metadata_provided!$A$2:$M$826, 3, FALSE) -> 2018 | E13: =VLOOKUP($C13, Egli_UPEC_metadata_provided!$A$2:$M$826, 4, FALSE) -> D1 | F13: =VLOOKUP($C13, Egli_UPEC_metadata_provided!$A$2:$M$826, 5, FALSE) -> m | G13: =VLOOKUP($C13, Egli_UPEC_metadata_provided!$A$2:$M$826, 6, FALSE) -> 1 | H13: =VLOOKUP($C13, Egli_UPEC_metadata_provided!$A$2:$M$826, 7, FALSE) -> 2 | I13: =VLOOKUP($C13, Egli_UPEC_metadata_provided!$A$2:$M$826, 8, FALSE) -> 60.637047 | J13: =VLOOKUP($C13, Egli_UPEC_metadata_provided!$A$2:$M$826, 9, FALSE) -> FALSE | K13: =VLOOKUP($C13, Egli_UPEC_metadata_provided!$A$2:$M$826, 10, FALSE) -> 0 | L13: =VLOOKUP($C13, Egli_UPEC_metadata_provided!$A$2:$M$826, 11, FALSE) -> invasive | M13: =VLOOKUP($C13, Egli_UPEC_metadata_provided!$A$2:$M$826, 12, FALSE) -> 0 | N13: =VLOOKUP($C13, Egli_UPEC_metadata_provided!$A$2:$M$826, 13, FALSE) -> 0 | O13: =VLOOKUP($C13, Egli_UPEC_metadata_provided!$A$2:$N$826, 14, FALSE) -> NA
... A1077: SAMEA111331914 | B1077: 722798-18 | C1077: 722798-18 | D1077: =VLOOKUP($C1077, Egli_UPEC_metadata_provided!$A$2:$M$826, 3, FALSE) -> #N/A | E1077: =VLOOKUP($C1077, Egli_UPEC_metadata_provided!$A$2:$M$826, 4, FALSE) -> #N/A | F1077: =VLOOKUP($C1077, Egli_UPEC_metadata_provided!$A$2:$M$826, 5, FALSE) -> #N/A | G1077: =VLOOKUP($C1077, Egli_UPEC_metadata_provided!$A$2:$M$826, 6, FALSE) -> #N/A | H1077: =VLOOKUP($C1077, Egli_UPEC_metadata_provided!$A$2:$M$826, 7, FALSE) -> #N/A | I1077: =VLOOKUP($C1077, Egli_UPEC_metadata_provided!$A$2:$M$826, 8, FALSE) -> #N/A | J1077: =VLOOKUP($C1077, Egli_UPEC_metadata_provided!$A$2:$M$826, 9, FALSE) -> #N/A | K1077: =VLOOKUP($C1077, Egli_UPEC_metadata_provided!$A$2:$M$826, 10, FALSE) -> #N/A | L1077: =VLOOKUP($C1077, Egli_UPEC_metadata_provided!$A$2:$M$826, 11, FALSE) -> #N/A | M1077: =VLOOKUP($C1077, Egli_UPEC_metadata_provided!$A$2:$M$826, 12, FALSE) -> #N/A | N1077: =VLOOKUP($C1077, Egli_UPEC_metadata_provided!$A$2:$M$826, 13, FALSE) -> #N/A | O1077: =VLOOKUP($C1077, Egli_UPEC_metadata_provided!$A$2:$N$826, 14, FALSE) -> #N/A

Sheet accession_map_downloaded
A1: sample_accession | B1: run_accession | C1: experiment_accession | D1: Genome_ID (TGNR-YY)
A2: SAMEA111330839 | B2: ERR10176577 | C2: ERX9713046 | D2: 100033-19
A3: SAMEA111330840 | B3: ERR10176578 | C3: ERX9713047 | D3: 100080-19
A4: SAMEA111330841 | B4: ERR10176579 | C4: ERX9713048 | D4: 100223-19
A5: SAMEA111330842 | B5: ERR10176580 | C5: ERX9713049 | D5: 100676-19
A6: SAMEA111330843 | B6: ERR10176581 | C6: ERX9713050 | D6: 100738-19
A7: SAMEA111330844 | B7: ERR10176582 | C7: ERX9713051 | D7: 100888-20
A8: SAMEA111330845 | B8: ERR10176583 | C8: ERX9713052 | D8: 100914-20
A9: SAMEA111330846 | B9: ERR10176584 | C9: ERX9713053 | D9: 100921-20
A10: SAMEA111330847 | B10: ERR10176585 | C10: ERX9713054 | D10: 100977-19
A11: SAMEA111330848 | B11: ERR10176586 | C11: ERX9713055 | D11: 101099-19
A12: SAMEA111330849 | B12: ERR10176587 | C12: ERX9713056 | D12: 102689-19
... A1077: SAMEA111331914 | B1077: ERR10176576 | C1077: ERX9713045 | D1077: 722798-18

Sheet Egli_UPEC_metadata_provided
A1: Genome label (TGNR-YY) | B1: TGNR_6 | C1: year | D1: Phylogroup_lineage | E1: Gender | F1: Immunosuppression | G1: Summe.der.Punkte.for.Charlson.Comorbidity.Index | H1: age | I1: papGII | J1: CTR_RES | K1: Invasiveness | L1: ICU.stay | M1: thirty_day_mortality_since_sample | N1: UTI.symptoms
A2: 100033-19 | B2: 100033 | C2: 2019 | D2: B2-2 | E2: w | F2: 0 | G2: 0 | H2: 68.814764 | I2: TRUE | J2: 0 | K2: invasive | L2: 0 | M2: 0 | N2: 1
A3: 100080-19 | B3: 100080 | C3: 2019 | D3: D3 | E3: w | F3: 0 | G3: 2 | H3: 59.119617 | I3: FALSE | J3: 0 | K3: invasive | L3: 0 | M3: 0 | N3: 0
A4: 100223-19 | B4: 100223 | C4: 2019 | D4: B2-2 | E4: m | F4: 1 | G4: 6 | H4: 65.487355 | I4: FALSE | J4: 0 | K4: invasive | L4: 0 | M4: 0 | N4: 1
A5: 100676-19 | B5: 100676 | C5: 2019 | D5: B1 | E5: w | F5: 1 | G5: 2 | H5: 42.805195 | I5: FALSE | J5: 0 | K5: invasive | L5: 0 | M5: 0 | N5: 0
A6: 100738-19 | B6: 100738 | C6: 2019 | D6: B2-2 | E6: w | F6: 0 | G6: 0 | H6: 52.235133 | I6: TRUE | J6: 0 | K6: invasive | L6: 0 | M6: 0 | N6: 1
A7: 100888-20 | B7: 100888 | C7: 2020 | D7: B2-2 | E7: w | F7: 0 | G7: 1 | H7: 77.913876 | I7: TRUE | J7: 0 | K7: invasive | L7: 1 | M7: 0 | N7: 0
A8: 100914-20 | B8: 100914 | C8: 2020 | D8: B2-2 | E8: m | F8: 0 | G8: 9 | H8: 85.069036 | I8: FALSE | J8: NA | K8: invasive | L8: 0 | M8: 0 | N8: 1
A9: 100977-19 | B9: 100977 | C9: 2019 | D9: B2-2 | E9: w | F9: 0 | G9: 1 | H9: 83.80041 | I9: TRUE | J9: NA | K9: invasive | L9: 0 | M9: 0 | N9: NA
A10: 101099-19 | B10: 101099 | C10: 2019 | D10: B2-2 | E10: w | F10: 0 | G10: 1 | H10: 69.736159 | I10: TRUE | J10: 0 | K10: invasive | L10: 0 | M10: 0 | N10: 1
A11: 102689-19 | B11: 102689 | C11: 2019 | D11: B2-2 | E11: w | F11: 0 | G11: 5 | H11: 48.639781 | I11: FALSE | J11: 0 | K11: invasive | L11: 0 | M11: 0 | N11: 0
A12: 102832-19 | B12: 102832 | C12: 2019 | D12: B2-2 | E12: m | F12: 1 | G12: 3 | H12: 56.434723 | I12: TRUE | J12: 0 | K12: invasive | L12: 0 | M12: 0 | N12: 0
A13: 102916-19 | B13: 102916 | C13: 2019 | D13: C | E13: w | F13: NA | G13: 2 | H13: 76.7054 | I13: FALSE | J13: 0 | K13: invasive | L13: 0 | M13: 0 | N13: NA
A14: 103140-20 | B14: 103140 | C14: 2020 | D14: B2-2 | E14: w | F14: 0 | G14: 0 | H14: 91.311005 | I14: TRUE | J14: 0 | K14: invasive | L14: 0 | M14: 0 | N14: 0
A15: 103514-20 | B15: 103514 | C15: 2020 | D15: D1 | E15: m | F15: 0 | G15: 0 | H15: 83.450444 | I15: TRUE | J15: 1 | K15: invasive | L15: 0 | M15: 1 | N15: 0
A16: 103713-19 | B16: 103713 | C16: 2019 | D16: B1 | E16: m | F16: 1 | G16: 2 | H16: 68.686261 | I16: FALSE | J16: NA | K16: invasive | L16: 0 | M16: 0 | N16: 0
A17: 103840-19 | B17: 103840 | C17: 2019 | D17: D1 | E17: m | F17: 0 | G17: 4 | H17: 84.713602 | I17: FALSE | J17: 0 | K17: invasive | L17: 1 | M17: 0 | N17: 1
A18: 103864-19 | B18: 103864 | C18: 2019 | D18: B2-1 | E18: m | F18: 1 | G18: 3 | H18: 31.606288 | I18: FALSE | J18: 1 | K18: invasive | L18: 1 | M18: 0 | N18: 0
A19: 104005-19 | B19: 104005 | C19: 2019 | D19: B1 | E19: w | F19: 0 | G19: 1 | H19: 75.576213 | I19: FALSE | J19: 0 | K19: invasive | L19: 0 | M19: 0 | N19: 1
A20: 104349-20 | B20: 104349 | C20: 2020 | D20: B2-2 | E20: w | F20: 1 | G20: 2 | H20: 72.396446 | I20: TRUE | J20: NA | K20: invasive | L20: 0 | M20: 0 | N20: 0
A21: 104606-20 | B21: 104606 | C21: 2020 | D21: B2-2 | E21: m | F21: 0 | G21: 0 | H21: 87.816815 | I21: FALSE | J21: 0 | K21: invasive | L21: 0 | M21: 0 | N21: 0
A22: 104977-19 | B22: 104977 | C22: 2019 | D22: B2-2 | E22: m | F22: 0 | G22: 3 | H22: 80.172249 | I22: TRUE | J22: 1 | K22: invasive | L22: 1 | M22: 0 | N22: 0
A23: 105056-19 | B23: 105056 | C23: 2019 | D23: D1 | E23: w | F23: 0 | G23: 2 | H23: 73.405332 | I23: FALSE | J23: 0 | K23: invasive | L23: 0 | M23: 0 | N23: 0
A24: 105099-20 | B24: 105099 | C24: 2020 | D24: B2-2 | E24: w | F24: 0 | G24: 1 | H24: 74.318524 | I24: TRUE | J24: 0 | K24: invasive | L24: 1 | M24: 0 | N24: 0
A25: 105252-19 | B25: 105252 | C25: 2019 | D25: D1 | E25: w | F25: 0 | G25: 0 | H25: 44.013671 | I25: FALSE | J25: 0 | K25: invasive | L25: 0 | M25: 0 | N25: 0
A26: 105320-19 | B26: 105320 | C26: 2019 | D26: B1 | E26: m | F26: 0 | G26: 8 | H26: 84.084757 | I26: FALSE | J26: 0 | K26: invasive | L26: 0 | M26: 0 | N26: 0
A27: 105436-19 | B27: 105436 | C27: 2019 | D27: B2-2 | E27: w | F27: NA | G27: NA | H27: 65.837321 | I27: TRUE | J27: 0 | K27: invasive | L27: NA | M27: NA | N27: NA
A28: 106778-20 | B28: 106778 | C28: 2020 | D28: B2-1 | E28: w | F28: 0 | G28: 0 | H28: 68.535885 | I28: FALSE | J28: NA | K28: invasive | L28: 0 | M28: 0 | N28: 0
A29: 106799-19 | B29: 106799 | C29: 2019 | D29: B2-1 | E29: m | F29: 0 | G29: 2 | H29: 78.255639 | I29: FALSE | J29: 0 | K29: invasive | L29: 1 | M29: 0 | N29: 0
A30: 106880-19 | B30: 106880 | C30: 2019 | D30: B2-1 | E30: m | F30: 0 | G30: 4 | H30: 66.143541 | I30: TRUE | J30: 1 | K30: invasive | L30: 1 | M30: 0 | N30: 1
A31: 107006-20 | B31: 107006 | C31: 2020 | D31: B2-1 | E31: w | F31: 0 | G31: 2 | H31: 71.198906 | I31: TRUE | J31: NA | K31: invasive | L31: 0 | M31: 0 | N31: 1
A32: 107068-19 | B32: 107068 | C32: 2019 | D32: B2-2 | E32: w | F32: 0 | G32: 1 | H32: 78.184552 | I32: FALSE | J32: 0 | K32: invasive | L32: 0 | M32: 1 | N32: 0
A33: 107096-19 | B33: 107096 | C33: 2019 | D33: D1 | E33: m | F33: 1 | G33: 3 | H33: 70.154477 | I33: FALSE | J33: 0 | K33: invasive | L33: 0 | M33: 0 | N33: 1
A34: 107962-20 | B34: 107962 | C34: 2020 | D34: B2-1 | E34: m | F34: 0 | G34: 0 | H34: 94.006835 | I34: TRUE | J34: 1 | K34: invasive | L34: 1 | M34: 0 | N34: 0
A35: 108013-20 | B35: 108013 | C35: 2020 | D35: B2-2 | E35: m | F35: 0 | G35: 6 | H35: 82.220096 | I35: FALSE | J35: 0 | K35: invasive | L35: 0 | M35: 0 | N35: 1
A36: 108036-19 | B36: 108036 | C36: 2019 | D36: B1 | E36: w | F36: NA | G36: 0 | H36: 37.695147 | I36: FALSE | J36: 0 | K36: invasive | L36: 0 | M36: 1 | N36: NA
A37: 108473-19 | B37: 108473 | C37: 2019 | D37: A | E37: m | F37: 0 | G37: 2 | H37: 78.731374 | I37: FALSE | J37: 0 | K37: invasive | L37: 0 | M37: 0 | N37: 0
A38: 108494-19 | B38: 108494 | C38: 2019 | D38: D1 | E38: m | F38: 1 | G38: 1 | H38: 54.818865 | I38: FALSE | J38: 0 | K38: invasive | L38: 0 | M38: NA | N38: 0
A39: 108798-19 | B39: 108798 | C39: 2019 | D39: B1 | E39: w | F39: 0 | G39: 0 | H39: 90.263841 | I39: FALSE | J39: 0 | K39: invasive | L39: 0 | M39: 0 | N39: 0
A40: 108842-19 | B40: 108842 | C40: 2019 | D40: B2-2 | E40: m | F40: 0 | G40: 5 | H40: 62.879016 | I40: FALSE | J40: 0 | K40: invasive | L40: 0 | M40: 0 | N40: 0
...

Sheet NOTES
A1: “TGNR | B1: 6”: 6 digit bacterial strain identifier (xxxxxx)
A2: “year”: Year of collection (20yy)
A3: These two columns together are how the genomes are labelled: xxxxxx-yy
A4: “Phylogroup | B4: lineage”: The E. coli phylogroup
A5: “Gender”: Sex of the patient (binary w/m)
A6: “Immunosuppression”: Whether the patient was immunosuppressed or not (binary 1/0)
A7: “Summe.der.Punkte.für.Charlson.Comorbidity.Index”: Sum of the CCI, calculated by Jessica Agnetti (an MD from the University Hospital of Basel)
A8: “age”: Age of the patient in years
A9: “papGII”: Whether the bacterial strain encoded papGII or not (binary 1/0)
A10: “CTR | B10: RES”: Whther the bacterial strain was phenotypically tested Ceftriaxone resistant or not (binary 1/0)
A11: “Invasiveness”: Whether the patient had a positive E. Coli blood culture within 7 days of collection of the urine sample (binary 1/0)
A12: “ICU.stay”: Whether the patient had to be admitted to the ICU during his hospital stay (binary 1/0)
A13: “thirty | B13: day | C13: mortality | D13: since | E13: sample”: Whether the patint died within 30 days after collection of the sample (binary 1/0)
A14: “UTI.symptoms”: Whether the patient experienced typical UTI symptoms
A17: Note: TGNR number is not unique!!! There are sometimes multiple sequences per TGNR id.
